Workbook
Name _1.: #REF!
Name _1_2: #REF!
Name _2._3.: #REF!
Name _2_3: #REF!
Name _3_4: #REF!
Name _5._6.: #REF!
Name _IVA1: #REF!
Name _IVA2: #REF!
Name A_IMPRESIÓN_IM: #REF!
Name Amort_comple: #REF!
Name Beg_Bal: #REF!
Name Contab1: #REF!
Name costo: #REF!
Name CPI: #REF!
Name D_Aduana: #REF!
Name diferido1: #REF!
Name End_Bal: #REF!
Name Extra_Pay: #REF!
Name fecha: #REF!
Name FUNT: #REF!
Name FUT: #REF!
Name Header_Row: ROW(#REF!)
Name hoja1: #REF!
Name hokja2: #REF!
Name i_diferido: #REF!
Name IAS: #REF!
Name Impto1: #REF!
Name Impto2: #REF!
Name Int: #REF!
Name Intangible: #REF!
Name Interest_Rate: #REF!
Name L_Adjust: #REF!
Name L_AJE_Tot: #REF!
Name L_CY_Beg: #REF!
Name L_CY_End: #REF!
Name L_PY_End: #REF!
Name L_RJE_Tot: #REF!
Name Last_Row: IF(Values_Entered,Header_Row+Number_of_Payments,Header_Row)
Name Leasing: #REF!
Name Loan_Amount: #REF!
Name Loan_Start: #REF!
Name Loan_Years: #REF!
Name nombre: #REF!
Name Num_Pmt_Per_Year: #REF!
Name Number_of_Payments: MATCH(0.01,End_Bal,-1)+1
Name OTROSFUT: #REF!
Name p: #REF!
Name PATRIMONIO: #REF!
Name Pay_Num: #REF!
Name Princ: #REF!
Name Prov_Ant_Prov: #REF!
Name Prov_Deud_Inc: #REF!
Name Prov_vacaciones: #REF!
Name Prov_varias: #REF!
Name RLI: #REF!
Name S_Adjust_Data: #REF!
Name S_AJE_Tot_Data: #REF!
Name S_CY_Beg_Data: #REF!
Name S_CY_End_Data: #REF!
Name S_PY_End_Data: #REF!

Sheet Balance Trib
A1: UNION NACIONAL DE ARTISTAS AG
A2: PROMOVER EL DESARROLLO DE ARTISTAS
A3: TERRANOVA #315
A4: PROVIDENCIA
A5: SANTIAGO
A6: 65.081.798-2
D7: Balance Tributario
D8: Acumulado mes/año
D9: 45656
A12: Cuenta Contable | B12: Valores Acumulados | D12: Saldos | F12: Inventario | H12: Resultados
B13: Débitos | C13: Créditos | D13: Deudor | E13: Acreedor | F13: Activo | G13: Pasivo | H13: Pérdida | I13: Ganancia
A14: 1-1-01-002 BANCO BCI | B14: 53070578 | C14: 24918139 | D14: 28152439 | E14: 0 | F14: 28152439 | G14: 0 | H14: 0 | I14: 0
A15: 1-1-04-001 ANTICIPOS A PROVEEDORES | B15: 60000 | C15: 0 | D15: 60000 | E15: 0 | F15: 60000 | G15: 0 | H15: 0 | I15: 0
A16: 1-1-04-002 ANTICIPO DE SUELDOS | B16: 163980 | C16: 311310 | D16: 0 | E16: 147330 | F16: 0 | G16: 147330 | H16: 0 | I16: 0
A17: 2-1-02-001 PROVEEDORES | B17: 929795 | C17: 1193124 | D17: 0 | E17: 263329 | F17: 0 | G17: 263329 | H17: 0 | I17: 0
A18: 2-1-02-002 HONORARIOS POR PAGAR | B18: 686434 | C18: 1404511 | D18: 0 | E18: 718077 | F18: 0 | G18: 718077 | H18: 0 | I18: 0
A19: 2-1-02-003 SUELDOS POR PAGAR | B19: 21089787 | C19: 22042766 | D19: 0 | E19: 952979 | F19: 0 | G19: 952979 | H19: 0 | I19: 0
A20: 2-1-02-007 CUENTAS POR PAGAR | B20: 0 | C20: 22502240 | D20: 0 | E20: 22502240 | F20: 0 | G20: 22502240 | H20: 0 | I20: 0
A21: 2-1-02-008 CTA CTE SCD | B21: 3566603 | C21: 10210277 | D21: 0 | E21: 6643674 | F21: 0 | G21: 6643674 | H21: 0 | I21: 0
A22: 2-1-03-001 AFP | B22: 2806408 | C22: 3347961 | D22: 0 | E22: 541553 | F22: 0 | G22: 541553 | H22: 0 | I22: 0
A23: 2-1-03-002 ISAPRES | B23: 753408 | C23: 1293807 | D23: 0 | E23: 540399 | F23: 0 | G23: 540399 | H23: 0 | I23: 0
A24: 2-1-03-003 FONASA - INP | B24: 603516 | C24: 603516 | D24: 0 | E24: 0 | F24: 0 | G24: 0 | H24: 0 | I24: 0
A25: 2-1-03-004 CCAF LOS ANDES | B25: 70209 | C25: 70209 | D25: 0 | E25: 0 | F25: 0 | G25: 0 | H25: 0 | I25: 0
... A39: Sub-Totales | B39: 288904658 | C39: 288904658 | D39: 231961197 | E39: 231961197 | F39: 207055164 | G39: 231961197 | H39: 24906033 | I39: 0
A40: Pérdidas / Ganancias | F40: 24906033 | I40: 24906033
A41: Total General | B41: 288904658 | C41: 288904658 | D41: 231961197 | E41: 231961197 | F41: 231961197 | G41: 231961197 | H41: 24906033 | I41: 24906033

Sheet Activos - pasivos 2023
A9: Activos
A10: 1-1-01-002 BANCO BCI | B10: 8510578
A11: 1-1-04-001 ANTICIPOS A PROVEEDORES | B11: 60000
A13: Saldo | B13: =SUM(B10:B12) -> 8570578
A20: Pasivos
A21: 1-1-04-002 ANTICIPO DE SUELDOS | B21: -147330
A22: 2-1-02-001 PROVEEDORES | B22: -140000
A23: 2-1-02-002 HONORARIOS POR PAGAR | B23: -718077
A24: 2-1-02-003 SUELDOS POR PAGAR | B24: -1830182
A25: 2-1-02-007 CUENTAS POR PAGAR | B25: -600
A26: 2-1-02-008 CTA CTE SCD | B26: -6643674
A27: 2-1-03-001 AFP | B27: -301801
A28: 2-1-03-002 ISAPRES | B28: -62824
A29: 2-1-03-003 FONASA - INP | B29: -71251
A30: 2-1-03-004 CCAF LOS ANDES | B30: -6680
A31: 2-1-03-005 MUTUAL SEGURIDAD IPS | B31: -18700
A32: 2-1-04-006 IMPUESTOS POR PAGAR | B32: -2149
... A35: 3-1-01-003 RESULTADOS ACUMULADOS | B35: 155264342
B36: =SUM(B21:B35) -> -32148961

Sheet Clsificado + EERR
A1: Empresa: | B1: UNION NACIONAL DE ARTISTAS AG
A2: Mes/Año: | B2: A Diciembre/2023
A3: Norma: | B3: Tributaria
A4: Moneda: | B4: Peso Chileno
C6: Balance General S.V.S. Tributario
A9: ACTIVOS
A10: ACTIVOS CIRCULANTES
A11: DISPONIBLE | D11: 8510578
A12: 1-1-01-002 BANCO BCI | D12: 8510578
A13: DEUDORES VARIOS | D13: -87330
A14: 1-1-04-001 ANTICIPOS A PROVEEDORES | D14: 60000
A15: 1-1-04-002 ANTICIPO DE SUELDOS | D15: -147330
A17: TOTAL ACTIVOS CIRCULANTES | D17: 8423248
A19: ACTIVOS FIJOS
A21: TOTAL ACTIVOS FIJOS | D21: 0
A23: OTROS ACTIVOS
A25: TOTAL OTROS ACTIVOS | D25: 0
A28: TOTAL ACTIVOS | D28: 8423248
C31: Balance General S.V.S. Tributario
A33: PASIVOS
A34: PASIVOS CIRCULANTES
A35: CUENTAS POR PAGAR | D35: 7502351
A36: 2-1-02-001 PROVEEDORES | D36: 140000
A37: 2-1-02-002 HONORARIOS POR PAGAR | D37: 718077
A38: 2-1-02-007 CUENTAS POR PAGAR | D38: 600
A39: 2-1-02-008 CTA CTE SCD | D39: 6643674
A40: ACREEDORES VARIOS | D40: 2291438
A41: 2-1-02-003 SUELDOS POR PAGAR | D41: 1830182
A42: 2-1-03-001 AFP | D42: 301801
A43: 2-1-03-002 ISAPRES | D43: 62824
A44: 2-1-03-003 FONASA - INP | D44: 71251
A45: 2-1-03-004 CCAF LOS ANDES | D45: 6680
A46: 2-1-03-005 MUTUAL SEGURIDAD IPS | D46: 18700
... A52: TOTAL PASIVOS CIRCULANTES | D52: 11112722
A54: PASIVOS LARGO PLAZO
A56: TOTAL PASIVOS LARGO PLAZO | D56: 0
A58: INTERES MINORITARIO
A60: TOTAL INTERES MINORITARIO | D60: 0
A62: PATRIMONIO
A63: PATRIMONIO | D63: 20888909
...

Sheet F.29

Sheet F29
P17: Impuesto Trabajador
P18: 0 | Q18: Ok
P59: Impuesto Trabajador
P60: 0 | Q60: Ok
P103: Impuesto Trabajador
P104: 0 | Q104: Ok
P147: Impuesto Trabajador
P148: 0 | Q148: Ok
P185: Impuesto Trabajador
P186: 0 | Q186: Ok
P232: Impuesto Trabajador
P233: 0 | Q233: Ok
P278: Impuesto Trabajador
P279: 1640 | Q279: Ok
P320: Impuesto Trabajador
P321: 0 | Q321: Ok
P363: Impuesto Trabajador
P364: 0 | Q364: Ok
P407: Impuesto Trabajador
P408: 0 | Q408: Ok
P450: Impuesto Trabajador
P451: 0 | Q451: Ok
P493: Impuesto Trabajador
P494: 0 | Q494: Ok
P519: =+P494+P451+P408+P364+P321+P233+P279+P186+P148+P104+P60+P18 -> 1640

Sheet Balance Query
A2: NomB | B2: UNION NACIONAL DE ARTISTAS AG | C2: =+B2 -> UNION NACIONAL DE ARTISTAS AG
A4: Balance | D4: Mes
A5: Grupo | B5: Cuenta | C5: Descripción | D5: 00 | E5: 01 | F5: 02 | G5: 03 | H5: 04 | I5: 05 | J5: 06 | K5: 07 | L5: 08 | M5: 09 | N5: 10 | O5: 11 | P5: 12 | Q5: Total general
A6: Activo | B6: 1-1-01-002 | C6: BANCO BCI | D6: 8510578 | E6: -3952102 | F6: -2006842 | G6: -2006869 | H6: -395120 | I6: 1776502 | J6: 2290217 | K6: -2524443 | L6: -548502 | M6: 2711067 | N6: -2998743 | O6: 26867019 | P6: 429677 | Q6: 28152439
B7: 1-1-04-001 | C7: ANTICIPOS A PROVEEDORES | D7: 60000 | Q7: 60000
B8: 1-1-04-002 | C8: ANTICIPO DE SUELDOS | D8: -147330 | M8: 0 | Q8: -147330
A9: Total Activo | D9: 8423248 | E9: -3952102 | F9: -2006842 | G9: -2006869 | H9: -395120 | I9: 1776502 | J9: 2290217 | K9: -2524443 | L9: -548502 | M9: 2711067 | N9: -2998743 | O9: 26867019 | P9: 429677 | Q9: 28065109
A10: Pasivo | B10: 2-1-02-001 | C10: PROVEEDORES | D10: -140000 | E10: 0 | F10: -70010 | G10: -141400 | I10: -140000 | J10: 130020 | K10: 79980 | L10: -70000 | M10: 0 | N10: 70000 | O10: 70000 | P10: -51919 | Q10: -263329
B11: 2-1-02-002 | C11: HONORARIOS POR PAGAR | D11: -718077 | Q11: -718077
B12: 2-1-02-003 | C12: SUELDOS POR PAGAR | D12: -1830182 | E12: 1806350 | F12: -27 | G12: 0 | H12: -1611749 | I12: 1611749 | J12: 0 | K12: 0 | L12: -1652498 | M12: 957850 | N12: 1264886 | O12: -1500324 | P12: 966 | Q12: -952979
B13: 2-1-02-007 | C13: CUENTAS POR PAGAR | D13: -600 | L13: -1640 | O13: -22500000 | Q13: -22502240
B14: 2-1-02-008 | C14: CTA CTE SCD | D14: -6643674 | E14: 0 | F14: 0 | G14: 0 | H14: 0 | J14: 0 | M14: 0 | N14: 0 | O14: 0 | Q14: -6643674
B15: 2-1-03-001 | C15: AFP | D15: -301801 | E15: 44935 | F15: 0 | G15: 0 | H15: 0 | I15: -258670 | J15: 254277 | K15: -26379 | L15: 14811 | M15: 138516 | N15: -110089 | O15: -25475 | P15: -271678 | Q15: -541553
B16: 2-1-03-002 | C16: ISAPRES | D16: -62824 | E16: 13212 | F16: 0 | G16: 0 | H16: 0 | I16: -49612 | J16: 48669 | K16: 0 | L16: 0 | M16: -8435 | N16: -172879 | O16: -37847 | P16: -270683 | Q16: -540399
B17: 2-1-03-003 | C17: FONASA - INP | D17: -71251 | E17: 7248 | F17: 0 | G17: 0 | H17: 0 | I17: -64764 | J17: 63754 | K17: -7094 | L17: 6081 | M17: 64532 | N17: 1494 | Q17: 0
B18: 2-1-03-004 | C18: CCAF LOS ANDES | D18: -6680 | E18: 679 | F18: 0 | G18: 0 | H18: 0 | I18: -6072 | J18: 5978 | K18: -665 | L18: 570 | M18: -7579 | N18: 13769 | Q18: 0
B19: 2-1-03-005 | C19: MUTUAL SEGURIDAD IPS | D19: -18700 | E19: 2809 | F19: 0 | G19: 0 | H19: 0 | I19: -16002 | J19: 15729 | K19: -1031 | L19: 884 | M19: 8257 | N19: -6744 | O19: -1513 | P19: -16422 | Q19: -32733
B20: 2-1-04-005 | C20: IMPUESTO UNICO | K20: 0 | Q20: 0
B21: 2-1-04-006 | C21: IMPUESTOS POR PAGAR | D21: -2149 | K21: -1640 | L21: 1640 | Q21: -2149
B22: 2-1-05-001 | C22: PROVISION VACACIONES | D22: -1316784 | E22: -104764 | F22: 590002 | G22: -34265 | H22: -121802 | I22: -13503 | J22: -76432 | K22: -145769 | L22: -240166 | Q22: -1463483
A23: Total Pasivo | D23: -11112722 | E23: 1770469 | F23: 519965 | G23: -175665 | H23: -1733551 | I23: 1063126 | J23: 441995 | K23: -102598 | L23: -1940318 | M23: 1153141 | N23: 1060437 | O23: -23995159 | P23: -609736 | Q23: -33660616
A24: Patrimonio | B24: 3-1-01-001 | C24: CAPITAL | D24: -176153251 | I24: -5000000 | J24: -5000000 | M24: -5000000 | O24: -5000000 | P24: -2000000 | Q24: -198153251
B25: 3-1-01-003 | C25: RESULTADOS ACUMULADOS | D25: 178842725 | Q25: 178842725
A26: Total Patrimonio | D26: 2689474 | I26: -5000000 | J26: -5000000 | M26: -5000000 | O26: -5000000 | P26: -2000000 | Q26: -19310526
A27: Gastos | B27: 5-2-01-001 | C27: REMUNERACIONES | E27: 1923932 | F27: 1923932 | G27: 1923932 | H27: 1923932 | I27: 1923932 | J27: 1957029 | K27: 2067867 | L27: 1972863 | M27: 944109 | N27: 1790045 | O27: 1972854 | P27: 1972854 | Q27: 22297281
B28: 5-2-01-002 | C28: APORTES PATRONALES | E28: 82937 | F28: 82937 | G28: 82937 | H28: 82937 | I28: 82937 | J28: 84347 | K28: 99365 | L28: 94291 | M28: 46883 | N28: 78261 | O28: 85286 | P28: 85286 | Q28: 988404
B29: 5-2-01-026 | C29: PUBLICIDAD | K29: 194040 | Q29: 194040
B30: 5-2-01-030 | C30: GASTOS NOTARIALES | L30: 111500 | M30: 74800 | Q30: 186300
B31: 5-2-01-031 | C31: GASTOS ADMINISTRATIVOS | G31: 71400 | J31: 79980 | K31: 50000 | P31: 51919 | Q31: 253299
B32: 5-2-01-032 | C32: ASESORIAS | E32: 70000 | F32: 70010 | G32: 70000 | I32: 140000 | J32: 70000 | K32: 70000 | L32: 70000 | M32: 70000 | N32: 70000 | O32: 70000 | P32: 70000 | Q32: 840010
B33: 5-2-01-036 | C33: GASTOS DE VACACIONES | E33: 104764 | F33: -590002 | G33: 34265 | H33: 121802 | I33: 13503 | J33: 76432 | K33: 145769 | L33: 240166 | Q33: 146699
A34: Total Gastos | E34: 2181633 | F34: 1486877 | G34: 2182534 | H34: 2128671 | I34: 2160372 | J34: 2267788 | K34: 2627041 | L34: 2488820 | M34: 1135792 | N34: 1938306 | O34: 2128140 | P34: 2180059 | Q34: 24906033
A35: Total general | D35: 0 | E35: 0 | F35: 0 | G35: 0 | H35: 0 | I35: 0 | J35: 0 | K35: 0 | L35: 0 | M35: 0 | N35: 0 | O35: 0 | P35: 0 | Q35: 0

Sheet Banco BCI
H1: Informe : Libro Mayor
A2: UNION NACIONAL DE ARTISTAS | H2: Sistema : Incluye toda la contabilización de todos los Sistemas.
A3: RUT: 65.081.798-2 | H3: Moneda: 01 - Peso Chileno
A4: TERRANOVA #315 COMUNA PROVIDENCIA CIUDAD STGO REGION METROPOLITANA | H4: Desde: 01-01-2024 Hasta: 31-12-2024
H5: Norma: Tributaria
A6: Conciliacion BCI | H6: Fecha: 31-03-2025
A7: Al 31 Diciembre 2024 | H7: Areas de Negocios:Todas
A9: Cuenta: | B9: 61798584 | H9: CUENTA | I9: FECHA | J9: N° COMPROBANTE | K9: TIPO | L9: DET.DE GASTO/INST.FINANCIERO | M9: DEBE | N9: HABER | O9: SALDO | P9: DESCRIPCION
A10: Nombre: | B10: 1-1-01-002 BANCO BCI
H11: SALDO ANTERIOR DE LA CUENTA: 1-1-01-002 BANCO BCI | M11: 8570578 | N11: 60000 | O11: 8510578
A13: Fecha | B13: N°Doc | C13: Concepto | D13: $ | H13: 1-1-01-002 BANCO BCI | I13: 02-01-2024 | J13: 00000041 | K13: E | M13: 0 | N13: 750962 | O13: 7759616 | P13: PAGO SUELDOS DIFERENCIAS 2023
C14: Saldo Según Contabilidad | D14: =+O67 -> 28152439 | H14: 1-1-01-002 BANCO BCI | I14: 02-01-2024 | J14: 00000041 | K14: E | M14: 0 | N14: 1055388 | O14: 6704228 | P14: PAGO SUELDOS DIFERENCIAS 2023
H15: 1-1-01-002 BANCO BCI | I15: 30-01-2024 | J15: 00000008 | K15: E | M15: 0 | N15: 645452 | O15: 6058776 | P15: PAGO SUELDO ENERO CATALINA TAPIA
C16: Cheques Girados y no Cobrados | D16: =SUM(D17:D19) -> 0 | H16: 1-1-01-002 BANCO BCI | I16: 30-01-2024 | J16: 00000008 | K16: E | M16: 0 | N16: 966297 | O16: 5092479 | P16: PAGO SUELDO ENERO CHRISTIAN TORRES
H17: 1-1-01-002 BANCO BCI | I17: 30-01-2024 | J17: 00000009 | K17: E | M17: 0 | N17: 70000 | O17: 5022479 | P17: PAGO FACT 8802 SOCIEDAD DE PROFESIONALES JV LTDA
H18: 1-1-01-002 BANCO BCI | I18: 30-01-2024 | J18: 00000011 | K18: E | M18: 0 | N18: 464003 | O18: 4558476 | P18: PAGO SCD
H19: 1-1-01-002 BANCO BCI | I19: 28-02-2024 | J19: 00000012 | K19: E | M19: 0 | N19: 645425 | O19: 3913051 | P19: PAGO SUELDO FEBRERO CATALINA TAPIA
H20: 1-1-01-002 BANCO BCI | I20: 28-02-2024 | J20: 00000012 | K20: E | M20: 0 | N20: 966297 | O20: 2946754 | P20: PAGO SUELDO FEBRERO CHRISTIAN TORRES
C21: Cargos Registrados en el Banco y No Contabilizados | D21: =SUM(D22:D26) -> 0 | H21: 1-1-01-002 BANCO BCI | I21: 28-02-2024 | J21: 00000014 | K21: E | M21: 0 | N21: 395120 | O21: 2551634 | P21: PAGO A SCD
H22: 1-1-01-002 BANCO BCI | I22: 28-03-2024 | J22: 00000015 | K22: E | M22: 0 | N22: 645452 | O22: 1906182 | P22: PAGO SUELDO MARZO CATALINA TAPIA
H23: 1-1-01-002 BANCO BCI | I23: 28-03-2024 | J23: 00000015 | K23: E | M23: 0 | N23: 966297 | O23: 939885 | P23: PAGO SUELDO MARZO CHRISTIAN TORRES
H24: 1-1-01-002 BANCO BCI | I24: 28-03-2024 | J24: 00000017 | K24: E | M24: 0 | N24: 395120 | O24: 544765 | P24: PAGO A SCD
H25: 1-1-01-002 BANCO BCI | I25: 09-04-2024 | J25: 00000020 | K25: E | M25: 0 | N25: 395120 | O25: 149645 | P25: PAGO A SCD
H26: 1-1-01-002 BANCO BCI | I26: 02-05-2024 | J26: 00000032 | K26: T | M26: 0 | N26: 645452 | O26: -495807 | P26: PAGO SUELDO ABRIL CATALINA TAPIA
H27: 1-1-01-002 BANCO BCI | I27: 02-05-2024 | J27: 00000032 | K27: T | M27: 0 | N27: 966297 | O27: -1462104 | P27: PAGO SUELDO ABRIL CHRISTIAN TORRES
H28: 1-1-01-002 BANCO BCI | I28: 27-05-2024 | J28: 00000038 | K28: I | M28: 5000000 | N28: 0 | O28: 3537896 | P28: TRASPASO DESDE LA CSD
C29: Abonos Registrados por el Banco y No Contabilizados | D29: =SUM(D30:D32) -> 0 | H29: 1-1-01-002 BANCO BCI | I29: 30-05-2024 | J29: 00000033 | K29: T | M29: 0 | N29: 645452 | O29: 2892444 | P29: PAGO SUELDO ABRIL CATALINA TAPIA
H30: 1-1-01-002 BANCO BCI | I30: 30-05-2024 | J30: 00000033 | K30: T | M30: 0 | N30: 966297 | O30: 1926147 | P30: PAGO SUELDO ABRIL CHRISTIAN TORRES
H31: 1-1-01-002 BANCO BCI | I31: 02-06-2024 | J31: 00000039 | K31: I | M31: 5000000 | N31: 0 | O31: 6926147 | P31: TRASPASO DESDE LA SCD
H32: 1-1-01-002 BANCO BCI | I32: 02-06-2024 | J32: 00000040 | K32: E | M32: 0 | N32: 280000 | O32: 6646147 | P32: PAGO FACTURAS JV ENE-FEB-MAR-ABR
H33: 1-1-01-002 BANCO BCI | I33: 06-06-2024 | J33: 00000037 | K33: E | M33: 0 | N33: 395120 | O33: 6251027 | P33: PAGO LEYES SOCIALES ABRIL- MAYO
C34: Abonos Contabilizados No Registrados en Banco | D34: =SUM(D35:D38) -> 0 | H34: 1-1-01-002 BANCO BCI | I34: 06-06-2024 | J34: 00000037 | K34: E | M34: 0 | N34: 395120 | O34: 5855907 | P34: PAGO LEYES SOCIALES ABRIL- MAYO
H35: 1-1-01-002 BANCO BCI | I35: 30-06-2024 | J35: 00000036 | K35: E | M35: 0 | N35: 981827 | O35: 4874080 | P35: PAGO SUELDOS JUNIO CHRISTIAN TORRES
H36: 1-1-01-002 BANCO BCI | I36: 30-06-2024 | J36: 00000036 | K36: E | M36: 0 | N36: 657716 | O36: 4216364 | P36: PAGO SUELDOS JUNIO CATALINA TAPIA
H37: 1-1-01-002 BANCO BCI | I37: 04-07-2024 | J37: 45 | K37: E | M37: 0 | N37: 70000 | O37: 4146364 | P37: PAGO FACTURA JV
H38: 1-1-01-002 BANCO BCI | I38: 11-07-2024 | J38: 50 | K38: E | M38: 0 | N38: 194040 | O38: 3952324 | P38: PAGO AVISOS ASAMBLEA MOSTRADOR Y MERCURIO
H39: 1-1-01-002 BANCO BCI | I39: 15-07-2024 | J39: 51 | K39: E | M39: 0 | N39: 50000 | O39: 3902324 | P39: PAGO PROGRAMADOR WEB
A40: Saldo Final | D40: =+D14+D16-D21+D29-D34 -> 28152439 | H40: 1-1-01-002 BANCO BCI | I40: 17-07-2024 | J40: 48 | K40: E | M40: 0 | N40: 79980 | O40: 3822344 | P40: PAGO FACTURA SUPER SOFTWARE
A41: Saldo según Cartola | D41: 28152438 | H41: 1-1-01-002 BANCO BCI | I41: 29-07-2024 | J41: 49 | K41: E | M41: 0 | N41: 657716 | O41: 3164628 | P41: PAGO SUELDOS JULIO Tapia Diaz Catalina Ignacia
A42: Diferencia | D42: =+D40-D41 -> 1 | H42: 1-1-01-002 BANCO BCI | I42: 29-07-2024 | J42: 49 | K42: E | M42: 0 | N42: 1070874 | O42: 2093754 | P42: PAGO SUELDOS JULIO Torres Castro Christian Mauricio
...

Sheet Ant Proveedor
A5: Asesorias Servicios JV Ltda
A6: Auditores Consultores Tributarios
C7: ANALISIS DE CUENTAS
C8: AL 31 de Octubre 2024
A11: Cuenta: | B11: 1-1-04-001 ANTICIPOS A PROVEEDORES
A13: Fecha | B13: Vouchers | C13: Factura | D13: Detalle | E13: $
A14: 45175 | B14: 96 | D14: Paga anticipo Israel Canales | E14: 60000
E20: =SUM(E14:E19) -> 60000
A21: Saldo Balance | E21: =+GETPIVOTDATA("'SALDOS'",'Balance Query'!$A$4,"Cuenta","1-1-04-001","Descripción","ANTICIPOS A PROVEEDORES ","PCTIPO","Activo") -> 60000
A22: Diferencia | E22: =+E20-E21 -> 0

Sheet Anticipo a Proveedores
A5: Asesorias Servicios JV Ltda
A6: Auditores Consultores Tributarios
B7: ANALISIS DE CUENTAS
B8: =+'Anticipo Sueldo'!B8:C8 -> AL 31 de Octubre 2024
A11: Cuenta: | B11: 1-1-04-001 ANTICIPO A PROVEEDORES
A13: Fecha | B13: Vouchers | C13: Detalle | D13: $
D24: =SUM(D14:D23) -> 0
A25: Saldo Balance | D25: =+GETPIVOTDATA("'SALDOS'",'Balance Query'!$A$4,"Cuenta","1-1-04-001","Descripción","ANTICIPOS A PROVEEDORES ","PCTIPO","Activo") -> 60000
A26: Diferencia | D26: =-D24+D25 -> 60000

Sheet Ant Sueldo
A5: Asesorias Servicios JV Ltda
A6: Auditores Consultores Tributarios
C7: ANALISIS DE CUENTAS
C8: AL 31 de Octubre 2024
A11: Cuenta: | B11: 1-1-04-002 ANTICIPO DE SUELDOS
A13: Fecha | B13: Vouchers | C13: Detalle | D13: $
A14: 45198 | B14: 68 | C14: ANTIC AGUINALDOS Tapia Diaz Catalina Ignacia | D14: -73665
A15: 45198 | B15: 68 | C15: ANTIC AGUINALDOS Torres Castro Christian Mauricio | D15: -73665
D21: =SUM(D14:D20) -> -147330
A22: Saldo Balance | D22: =+GETPIVOTDATA("'SALDOS'",'Balance Query'!$A$4,"Cuenta","1-1-04-002","Descripción","ANTICIPO DE SUELDOS","PCTIPO","Activo") -> -147330
A23: Diferencia | D23: =+D21-D22 -> 0

Sheet Proveedores
A5: Asesorias Servicios JV Ltda
A6: Auditores Consultores Tributarios
D7: ANALISIS DE CUENTAS
D8: AL 31 de Octubre 2024
A11: Cuenta: | B11: 2-1-02-001 PROVEEDORES
A13: Fecha | B13: Dcto | C13: Numero | D13: Factura | E13: Detalle | F13: $
A14: 45345 | B14: FA | C14: 8882 | D14: 76.352.563-5 | E14: ASESORIAS Y SERVICIOS JV SPA | F14: -10
A15: 45261 | B15: FA | C15: 8632 | D15: 96.909.050-3 | E15: FACT 8632 SOCIEDAD DE PROFESIONALES JV LTDA | F15: -70000
A16: 45626 | B16: FA | C16: 9750 | D16: 96.909.050-3 | E16: FACT N9750 SOC. DE PROFESIONALES JV | F16: -70000
A17: 45382 | B17: FA | C17: 47180 | D17: 96.909.050-3 | E17: FACT 47180 LA PLAZA SA | F17: -35700
A18: 45382 | B18: FA | C18: 47181 | D18: 96.909.050-3 | E18: FACT 47181 LA PLAZA SA | F18: -35700
A19: 45644 | B19: FA | C19: 51280 | D19: 76.486.150-7 | E19: FACT 51280 SUPER SOFTWARE SPA | F19: -51919
F23: =SUM(F14:F22) -> -263329
A24: Saldo Balance | F24: =+GETPIVOTDATA("'SALDOS'",'Balance Query'!$A$4,"Cuenta","2-1-02-001","Descripción","PROVEEDORES ","PCTIPO","Pasivo") -> -263329
A25: Diferencia | F25: =+F23-F24 -> 0

Sheet Anticipo Sueldo
A5: Asesorias Servicios JV Ltda
A6: Auditores Consultores Tributarios
B7: ANALISIS DE CUENTAS
B8: =+Honorarios!B8 -> AL 31 de Octubre 2024
A11: Cuenta: | B11: 1-1-04-002 ANTICIPO DE SUELDOS
A13: Fecha | B13: Vouchers | C13: Detalle | D13: $
D20: =SUM(D14:D19) -> 0
A21: Saldo Balance | D21: =+GETPIVOTDATA("'SALDOS'",'Balance Query'!$A$4,"Cuenta","1-1-04-002","Descripción","ANTICIPO DE SUELDOS ","PCTIPO","Activo") -> -147330
A22: Diferencia | D22: =+D20-D21 -> 147330

Sheet Sueldos
A5: Asesorias Servicios JV Ltda
A6: Auditores Consultores Tributarios
B7: ANALISIS DE CUENTAS
B8: =+Proveedores!D8 -> AL 31 de Octubre 2024
A11: Cuenta: | B11: 2-1-02-003 SUELDOS POR PAGAR
A13: Fecha | B13: Vouchers | C13: Rut | D13: Detalle | E13: $
A14: 45107 | B14: 35 | C14: 18955650 | D14: LIQUIDO A PAGO Tapia Diaz Catalina Ignacia | E14: -630170
A15: 45107 | B15: 56 | C15: 18955650 | D15: Paga sueldo Catalina Tapia | E15: 614202
A16: 45137 | B16: 37 | C16: 18955650 | D16: LIQUIDO A PAGO Tapia Diaz Catalina Ignacia | E16: -630170
A17: 45138 | B17: 110 | C17: 18955650 | D17: Paga sueldo Catalina Tapia | E17: 614202
A18: 45198 | B18: 68 | C18: 18955650 | D18: LIQUIDO A PAGO Tapia Diaz Catalina Ignacia | E18: -651664
A19: 45199 | B19: 83 | C19: 18955650 | D19: Paga sueldo Catalina Tapia | E19: 630170
A20: 45229 | B20: 75 | C20: 18955650 | D20: LIQUIDO A PAGO Tapia Diaz Catalina Ignacia | E20: -631557
A21: 45230 | B21: 84 | C21: 18955650 | D21: Paga sueldo Catalina Tapia | E21: 614202
A22: 45260 | B22: 82 | C22: 18955650 | D22: LIQUIDO A PAGO Tapia Diaz Catalina Ignacia | E22: -631557
A23: 45262 | B23: 138 | C23: 18955650 | D23: pago de sueldo Tapia Diaz Catalina Ignacia | E23: 614202
A24: 45290 | B24: 131 | C24: 18955650 | D24: LIQUIDO A PAGO Tapia Diaz Catalina Ignacia | E24: -680177
A25: 45293 | B25: 41 | C25: 18955650 | D25: PAGO SUELDOS DIFERENCIAS 2023 CATALINA TAPIA | E25: 750962
... A29: 45657 | B29: 84 | C29: 18955650 | D29: LIQUIDO A PAGO Tapia Diaz Catalina Ignacia | E29: -657716
D37: Catalina Tapia | E37: =SUM(E14:E36) -> -747375
A38: 45107 | B38: 35 | C38: 10491400 | D38: LIQUIDO A PAGO Torres Castro Christian Mauricio | E38: -971375
A39: 45107 | B39: 59 | C39: 10491400 | D39: Paga sueldo Christian Torres | E39: 919263
A40: 45137 | B40: 37 | C40: 10491400 | D40: LIQUIDO A PAGO Torres Castro Christian Mauricio | E40: -942225
A41: 45137 | B41: 60 | C41: 10491400 | D41: Paga sueldo Christian Torres | E41: 919263
A42: 45198 | B42: 68 | C42: 10491400 | D42: LIQUIDO A PAGO Torres Castro Christian Mauricio | E42: -949162
A43: 45199 | B43: 83 | C43: 10491400 | D43: Paga sueldo Christian Torres | E43: 942226
A44: 45229 | B44: 75 | C44: 10491400 | D44: LIQUIDO A PAGO Torres Castro Christian Mauricio | E44: -948703
A45: 45230 | B45: 84 | C45: 10491400 | D45: Paga sueldo Christian Torres | E45: 942226
A46: 45260 | B46: 82 | C46: 10491400 | D46: LIQUIDO A PAGO Torres Castro Christian Mauricio | E46: -948703
A47: 45262 | B47: 138 | C47: 10491400 | D47: pago de sueldo Torres Castro Christian Mauricio | E47: 942226
A48: 45290 | B48: 131 | C48: 10491400 | D48: LIQUIDO A PAGO Torres Castro Christian Mauricio | E48: -966901
A49: 45293 | B49: 41 | C49: 10491400 | D49: PAGO SUELDOS DIFERENCIAS 2023 CHRISTIAN TORRES | E49: 1055388
... A52: 45657 | B52: 84 | C52: 10491400 | D52: LIQUIDO A PAGO Castillo Ruiz Maria Fernanda | E52: -841641
D59: Christian Torres | E59: =SUM(E38:E58) -> -205603
E61: =+E59+E37 -> -952978
A62: Saldo Balance | E62: =GETPIVOTDATA("'SALDOS'",'Balance Query'!$A$4,"Cuenta","2-1-02-003","Descripción","SUELDOS POR PAGAR","PCTIPO","Pasivo") -> -952979
A63: Diferencia | E63: =+E61-E62 -> 1

Sheet Honorarios
A5: Asesorias Servicios JV Ltda
A6: Auditores Consultores Tributarios
B7: ANALISIS DE CUENTAS
B8: =Sueldos!B8 -> AL 31 de Octubre 2024
A11: Cuenta: | B11: 2-1-02-002 HONORARIOS POR PAGAR
A13: Fecha | B13: Bol | C13: Vouchers | D13: Detalle | E13: $
A14: 43100 | B14: 139 | D14: JAVIERA MILAGROS NOVOA CUBILLO | E14: -482888
A15: 43829 | B15: 85 | D15: BH.85 VICTOR IGNACIO ESCOBEDO CASTRO | E15: 500
A16: 43836 | B16: 69 | D16: BH 69 CAROLINA SOLEDAD NEGRON MARAMB | E16: 985
A17: 43898 | B17: 4 | D17: MABE O-LAN MARAMBIO VIDAL | E17: -118337
A18: 43914 | B18: 5 | D18: MABE O-LAN MARAMBIO VIDAL | E18: -118337
E24: =SUM(E14:E23) -> -718077
A25: Saldo Balance | E25: =+GETPIVOTDATA("'SALDOS'",'Balance Query'!$A$4,"Cuenta","2-1-02-002","Descripción","HONORARIOS POR PAGAR ","PCTIPO","Pasivo") -> -718077
A26: Diferencia | E26: =+E24-E25 -> 0

Sheet Cta Pagar
A5: Asesorias Servicios JV Ltda
A6: Auditores Consultores Tributarios
B7: ANALISIS DE CUENTAS
B8: =+Honorarios!B8 -> AL 31 de Octubre 2024
A11: Cuenta: | B11: 2-1-02-007 CUENTAS POR PAGAR
A13: Fecha | B13: Vouchers | C13: Detalle | D13: $
A14: 44824 | B14: 85 | C14: PAGA F29 AGOSTO | D14: -600
A15: 45535 | B15: 54 | C15: PAGA F29 AGOSTO 2024 | D15: -1640
A16: 45615 | B16: 94 | C16: PAGO RECIBIDO FONDO ESTATAL GANADO | D16: -22500000
D18: =SUM(D14:D17) -> -22502240
A19: Saldo Balance | D19: =+GETPIVOTDATA("'SALDOS'",'Balance Query'!$A$4,"Cuenta","2-1-02-007","Descripción","CUENTAS POR PAGAR ","PCTIPO","Pasivo") -> -22502240
A20: Diferencia | D20: =+D18-D19 -> 0

Sheet Cta Cte SCD
A5: Asesorias Servicios JV Ltda
A6: Auditores Consultores Tributarios
B7: ANALISIS DE CUENTAS
B8: =+Honorarios!B8 -> AL 31 de Octubre 2024
A11: Cuenta: | B11: 2-1-02-008 CTA CTE SCD
A13: Fecha | B13: Vouchers | C13: Detalle | D13: $
A14: 43962 | B14: 96 | C14: Contabiliza leyes sociales Abril | D14: -524277
A15: 43981 | B15: 98 | C15: CONTABILIZA Sueldo Mayo | D15: -393292
A16: 43982 | B16: 109 | C16: CONTABILIZA FACT. 260636 COMPAÃ‘ÃA DE SEGUROS DE VIDA CAMAR | D16: -50053
A17: 43982 | B17: 108 | C17: CONTABILIZA FACT. 37576 COMPAÃ‘ÃA DE SEGUROS DE VIDA CAMARA | D17: -192
A18: 43994 | B18: 97 | C18: Contabiliza leyes sociales Mayo | D18: -168411
A19: 44012 | B19: 111 | C19: CONTABILIZA FACT. 263429 COMPAÃ‘ÃA DE SEGUROS DE VIDA CAMAR | D19: -50018
A20: 44012 | B20: 110 | C20: CONTABILIZA FACT. 38008 COMPAÃ‘ÃA DE SEGUROS DE VIDA CAMARA | D20: -192
A21: 44012 | B21: 99 | C21: CONTABILIZA Sueldo Junio | D21: -382352
A22: 44025 | B22: 115 | C22: CONTABILIZA LEYES SOCIALES JUNIO | D22: -166155
A23: 44043 | B23: 173 | C23: CONTABILIZA FACT. 20818 Morales Besa y CompaÃ±ia Limitada | D23: -45824
A24: 44043 | B24: 117 | C24: CONTABILIZA FACT. 267673 COMPAÃ‘ÃA DE SEGUROS DE VIDA CAMAR | D24: -49968
A25: 44043 | B25: 116 | C25: CONTABILIZA FACT. 38700 COMPAÃ‘ÃA DE SEGUROS DE VIDA CAMARA | D25: -192
... A34: 44104 | B34: 141 | C34: CONTABILIZA SUELDO SEPTIEMBRE | D34: -446769
A35: 30/09/2020 | B35: 179 | C35: CONTABILIZA ANTIC AGUINALDOS Pinto Ortega Daniela Judith | D35: -59503
A36: 44117 | B36: 158 | C36: CONTABILIZA LEYES SOCIALES SEPTIEMBRE | D36: -142469
A37: 44134 | B37: 174 | C37: CONTABILIZA FACT. 40404 COMPAÃ‘ÃA DE SEGUROS DE VIDA CAMARA | D37: -193
A38: 44134 | B38: 157 | C38: CONTABILIZA SUELDO OCTUBRE | D38: -430614
A39: 44134 | B39: 153 | C39: CONTABILIZA F.29 ABRIL | D39: -13724
A40: 44134 | B40: 153 | C40: CONTABILIZA F.29 MARZO | D40: -42357
A41: 44148 | B41: 172 | C41: CONTABILIZA LEYES SOCIALES OCTUBRE | D41: -120078
A42: 44153 | B42: 166 | C42: FACT. ASESORIAS Y SERVICIOS JV SPA DE MARZO A SEPTIEMBRE | D42: -490000
A43: 44154 | B43: 176 | C43: CONTABILIZA FACT. 280666 COMPAÃ‘ÃA DE SEGUROS DE VIDA CAMAR | D43: -37533
A44: 44161 | B44: 170 | C44: CONTABILIZA F.29 OCTUBRE | D44: -114426
A45: 44161 | B45: 169 | C45: CONTABILIZA FACT. 5030 ASESORIAS Y SERVICIOS JV SPA | D45: -70000
A46: 44165 | B46: 177 | C46: CONTABILIZA FACT. 281854 COMPAÃ‘ÃA DE SEGUROS DE VIDA CAMAR | D46: -37790
A47: 44165 | B47: 175 | C47: CONTABILIZA FACT. 40977 COMPAÑÍA DE SEGUROS DE VIDA CAMARA S | D47: -195
... A158: 44926 | B158: 111 | C158: Paga fa 43910 La plaza | D158: -23800
A159: 10/01/2023 | B159: 7 | C159: PAGO LEYES SOCIALES DICIEMBRE | D159: -278867
A160: 44951 | B160: 100 | C160: Contabiliza devolucion a Scd | D160: 40093625
A161: 30/01/2023 | B161: 5 | C161: Pago de sueldo a Tapia Diaz | D161: -614202
A162: 10/02/2023 | B162: 8 | C162: PAGO LEYES SOCIALES ENERO | D162: -156609
A163: 28/02/2023 | B163: 6 | C163: CONTABILIZA SUELDO Febrero Tapia Diaz | D163: -614202
A164: 07/03/2023 | B164: 29 | C164: Paga 7781 7782 y 7784 ASESORIAS Y SERVICIOS JV SPA | D164: -140000
A165: 10/03/2023 | B165: 14 | C165: PAGO LEYES SOCIALES FEBRERO | D165: -156609
...

Sheet Afp
A5: Asesorias Servicios JV Ltda
A6: Auditores Consultores Tributarios
B7: ANALISIS DE CUENTAS
B8: =+Proveedores!D8 -> AL 31 de Octubre 2024
A11: Cuenta: | B11: 2-1-03-001 AFP
A13: Fecha | B13: Vouchers | C13: Detalle | D13: $
A14: 45626 | B14: 82 | C14: AFP | D14: =-52972+1803 -> -51169
A15: 45626 | B15: 82 | C15: AFP | D15: -218706
A16: 45657 | B16: 84 | D16: -52972
A17: 45657 | B17: 84 | D17: -218706
D20: =SUM(D14:D19) -> -541553
A21: Saldo Balance | D21: =+GETPIVOTDATA("'SALDOS'",'Balance Query'!$A$4,"Cuenta","2-1-03-001","Descripción","AFP ","PCTIPO","Pasivo") -> -541553
A22: Diferencia | D22: =+D20-D21 -> 0

Sheet Isapre
A5: Asesorias Servicios JV Ltda
A6: Auditores Consultores Tributarios
B7: ANALISIS DE CUENTAS
B8: =+Proveedores!D8 -> AL 31 de Octubre 2024
A11: Cuenta: | B11: 2-1-03-002 ISAPRES
A13: Fecha | B13: Vouchers | C13: Detalle | D13: $
A14: 45626 | B14: 82 | C14: ISAPRE | D14: -269716
A15: 45657 | B15: 84 | D15: -270683
D17: =SUM(D14:D16) -> -540399
A18: Saldo Balance | D18: =+GETPIVOTDATA("'SALDOS'",'Balance Query'!$A$4,"Cuenta","2-1-03-002","Descripción","ISAPRES ","PCTIPO","Pasivo") -> -540399
A19: Diferencia | D19: =+D17-D18 -> 0

Sheet Fonasa
A5: Asesorias Servicios JV Ltda
A6: Auditores Consultores Tributarios
B7: ANALISIS DE CUENTAS
B8: =+Proveedores!D8 -> AL 31 de Octubre 2024
A11: Cuenta: | B11: 2-1-03-003 FONASA - INP
A13: Fecha | B13: Vouchers | C13: Detalle | D13: $
D16: =SUM(D14:D15) -> 0
A17: Saldo Balance | D17: =GETPIVOTDATA("'SALDOS'",'Balance Query'!$A$4,"Cuenta","2-1-03-003","Descripción","FONASA - INP ","PCTIPO","Pasivo") -> 0
A18: Diferencia | D18: =+D16-D17 -> 0

Sheet Ccaf los andes
A5: Asesorias Servicios JV Ltda
A6: Auditores Consultores Tributarios
B7: ANALISIS DE CUENTAS
B8: =+Proveedores!D8 -> AL 31 de Octubre 2024
A11: Cuenta: | B11: 2-1-03-004 CCAF LOS ANDES
D24: =SUM(D14:D23) -> 0
A25: Saldo Balance | D25: =GETPIVOTDATA("'SALDOS'",'Balance Query'!$A$4,"Cuenta","2-1-03-004","Descripción","CCAF LOS ANDES","PCTIPO","Pasivo") -> 0
A26: Diferencia | D26: =+D24-D25 -> 0

Sheet Mutual
A5: Asesorias Servicios JV Ltda
A6: Auditores Consultores Tributarios
B7: ANALISIS DE CUENTAS
B8: =+Proveedores!D8 -> AL 31 de Octubre 2024
A11: Cuenta: | B11: 2-1-03-005 MUTUAL SEGURIDAD IPS
A13: Fecha | B13: Vouchers | C13: Detalle | D13: $
A14: 45626 | B14: 82 | C14: ACC DEL TRABAJO | D14: =-16422+111 -> -16311
A15: 45657 | B15: 84 | D15: -16422
D17: =SUM(D14:D16) -> -32733
A18: Saldo Balance | D18: =+GETPIVOTDATA("'SALDOS'",'Balance Query'!$A$4,"Cuenta","2-1-03-005","Descripción","MUTUAL SEGURIDAD IPS ","PCTIPO","Pasivo") -> -32733
A19: Diferencia | D19: =+D17-D18 -> 0

Sheet Impuestos por Pagar
A5: Asesorias Servicios JV Ltda
A6: Auditores Consultores Tributarios
B7: ANALISIS DE CUENTAS
B8: =+Proveedores!D8 -> AL 31 de Octubre 2024
A11: Cuenta: | B11: 2-1-04-006 IMPUESTOS POR PAGAR
A13: Fecha | B13: Vouchers | C13: Detalle | D13: $
D18: =SUM(D14:D17) -> 0
A19: Saldo Balance | D19: =GETPIVOTDATA("'SALDOS'",'Balance Query'!$A$4,"CpbMes","06","Cuenta","2-1-04-006","Descripción","IMPUESTOS POR PAGAR","PCTIPO","Pasivo") -> 0
A20: Diferencia | D20: =+D18-D19 -> 0

Sheet Provision 
A5: Asesorias Servicios JV Ltda
A6: Auditores Consultores Tributarios
B7: ANALISIS DE CUENTAS
B8: =+Proveedores!D8 -> AL 31 de Octubre 2024
A11: Cuenta: | B11: 2-1-05-001 PROVISIONES VARIAS
A13: Fecha | B13: Vouchers | C13: Detalle | D13: $
A14: 45535 | B14: 18955650-0 | C14: TAPIA DIAZ, CATALINA IGNACIA | D14: -828131.27
A15: 45535 | B15: 10491400-4 | C15: TORRES CASTRO, CHRISTIAN MAURICIO | D15: -635350.76
D22: =SUM(D14:D21) -> -1463482
A23: Saldo Balance | D23: =+GETPIVOTDATA("'SALDOS'",'Balance Query'!$A$4,"Cuenta","2-1-05-001","Descripción","PROVISION VACACIONES ","PCTIPO","Pasivo")+1 -> -1463482
A24: Diferencia | D24: =+D22-D23 -> -0.024666667
A30: Rut | B30: Nombre | C30: ID | D30: Fecha de ingreso | E30: CCSAP | F30: CC nombre | G30: MES 1 | H30: MES 2 | I30: MES 3 | J30: Prom_Renta Variable | K30: SUELDO BASE PACTADO | L30: Dias de Vacaciones Totales | M30: Provision Acum_Vac para Sueldo Base + Renta Variable
A31: 18955650-0 | B31: TAPIA DIAZ, CATALINA IGNACIA | C31: UNA | D31: 44440 | E31: 0 | F31: Unión Nacional de Artistas - UNA | G31: 0 | H31: 0 | I31: 0 | J31: 0 | K31: 577766 | L31: 43 | M31: 828131.27
A32: 10491400-4 | B32: TORRES CASTRO, CHRISTIAN MAURICIO | C32: UNA | D32: 44986 | E32: 0 | F32: Unión Nacional de Artistas - UNA | G32: 0 | H32: 0 | I32: 0 | J32: 0 | K32: 845631 | L32: 22.54 | M32: 635350.76
G35: 0 | H35: 0 | I35: 0 | J35: 0 | L35: =SUM(L31:L32) -> 65.54 | M35: =SUM(M31:M32) -> 1463482

Sheet Cta Capital
A5: Asesorias Servicios JV Ltda
A6: Auditores Consultores Tributarios
B7: ANALISIS DE CUENTAS
B8: =+Honorarios!B8 -> AL 31 de Octubre 2024
A11: Cuenta: | B11: 3-1-01-001 CAPITAL
A13: Fecha | B13: Vouchers | C13: Detalle | D13: $
A14: 43831 | B14: 0 | C14: Movimiento de Apertura | D14: -80130001
A15: 43861 | B15: 4 | C15: Transferencia SCD Enero 2020 | D15: -6000000
A16: 43879 | B16: 31 | C16: Aporte de miembri de la UNA Prodanza | D16: -272500
A17: 43927 | B17: 73 | C17: Aporte SCD | D17: -3500000
A18: 43959 | B18: 86 | C18: Aporte SCD | D18: -8500000
A19: 44088 | B19: 131 | C19: Aporte SCD | D19: -2866836
A20: 44088 | B20: 152 | C20: Aporte SCD | D20: -8033914
A21: 44137 | B21: 178 | C21: Aporte SCD | D21: -950000
A22: 44169 | B22: 194 | C22: Aporte SCD | D22: -950000
A23: 44196 | B23: 193 | C23: Aporte SCD | D23: -950000
A24: 44554 | B24: 166 | C24: Aporte SCD | D24: -22000000
A25: 44914 | B25: 106 | C25: Aporte SCD | D25: -20000000
... A35: 45645 | B35: 93 | C35: Aporte SCD | D35: -2000000
D37: =SUM(D14:D36) -> -198153251
A38: Saldo Balance | D38: =+GETPIVOTDATA("'SALDOS'",'Balance Query'!$A$4,"Cuenta","3-1-01-001","Descripción","CAPITAL ","PCTIPO","Patrimonio") -> -198153251
A39: Diferencia | D39: =+D37-D38 -> 0
